# 10장. 예외 처리

## 예외 처리

- 코루인의 작동 원리 중 아주 중요한 기능
- 코루틴 역시 잡히지 않은 예외가 발생하면 종료됨
    - 부모도 종료시키고, 그 부모의 자식들 모두 취소됨
    - *내가 종료되면 부모님 형제들 다 취소된다 ~*
- 예외가 발생하면 자기 자신을 취소하고, 예외를 부모로 전파
    
    ```kotlin
    fun main(): Unit = runBlocking {
        launch {
            launch {
                delay(1000)
                throw Error("Some error")
            }
    
            launch {
                delay(21000)
                println("Will not be printed")
            }
    
            launch {
                delay(500)
                println("Will be printed")
            }
        }
    }
    
    /*
    출력 결과
    -----------
    Will be printed
    Exception in thread "main" java.lang.Error: Some error...
    */
    ```
    
    - 예외 발생 → 부모로 전파 (launch)
    - 그 부모 역시 자기 자신과 자식 모두 취소하고, 예외 부모로 전파 (runBlocking)
    - runBlocking은 부모가 없는 루트 코루틴 → 예외를 다시 던지고 프로그램 종료됨

## 코루틴 종료 멈추기

- 코루틴 간의 상호작용은 잡을 통해서 일어나기 때문에, 코루틴 빌더 내부에서 새로운 코루틴 빌더를 try-catch 문을 통해 래핑하는 건 도움이 되지 않음 (무시됨)

### SupervisorJob

- 자식에서 발생한 모든 예외를 무시할 수 있음
    
    ![Untitled](https://www.notion.so/image/https%3A%2F%2Fprod-files-secure.s3.us-west-2.amazonaws.com%2Fd4809f18-a915-4e30-8b11-8f015eacff00%2F556c646e-6834-49bf-a07b-dec25ac8d8e4%2FUntitled.png?table=block&id=0ecafdbb-ee9f-4390-9036-cf4e0e37d75e&spaceId=d4809f18-a915-4e30-8b11-8f015eacff00&width=1510&userId=92588618-7e5f-4fa1-b99e-a00a9b224710&cache=v2)
    

- 일반적으로 **다수의 코루틴을 시작하는 스코프로 사용**됨
    
    ```kotlin
    fun main(): Unit = runBlocking {
        val scope = CoroutineScope(SupervisorJob())
        scope.launch { ... }
    }
    ```
    
- 흔한 실수: **부모 코루틴의 인자로 사용**
    
    ```kotlin
    // No: SupervisorJob은 단 하나의 자식만 가지기 때문에 
    //     예외 처리에 아무런 도움이 되지 않음
    fun main(): Unit = runBlocking {
        launch(SupervisorJob()) { ... }
    }
    
    // Yes: 같은 잡을 다수의 코루틴에서 컨텍스트로 사용하는 것이 좀 더 나은 방법
    fun main(): Unit = runBlocking {
        val job = SupervisorJob()
        launch(job) { ... }
        // job.complete()
        // job.join()
        // 해야 이게 프로그램 종료댐
    }
    ```
    

- Children of a supervisor job can fail independently of each other.
    - 출처: https://kotlinlang.org/api/kotlinx.coroutines/kotlinx-coroutines-core/kotlinx.coroutines/-supervisor-job.html

### supervisorScope

- 코루틴 빌더를 `supervisorScope`로 래핑
- 다른 코루틴에서 발생한 예외를 무시하고 부모와의 연결을 유지함
    
    ```kotlin
    fun main(): Unit = runBlocking {
        supervisorScope {
            launch {
                delay(1000)
                throw Error("Some error")
            }
            
            launch {
                delay(2000)
                println("Will be printed")
            }
        }
        
        delay(1000)
        println("Done")
    }
    
    /*
    출력 결과
    -----------
    Exception...
    Will be printed
    (1s later)
    Done
    */
    ```
    

- supervisorScope는 단지 중단 함수일 뿐이며, 중단 함수 본체를 래핑하는 데 사용됨
- 일반적으로 **서로 무관한 다수의 작업을 스코프 내에서 실행**하게 사용함
    
    ```kotlin
    suspend fun notifyAnalytics(actions: List<UserAction>) =
        supervisorScope {
            action.forEach { action -> 
                launch {
                    notifyAnalytics(action)
                }
            }
        }
    ```
    

- supervisorScope는 withContext(SupervisorJob())으로 대체될 수 없음
    - 코루틴은 각각 자신만의 잡이 있고, 잡을 다른 코루틴에 전달하여 부모 관계를 맺음
    - SupervisorJob이 withContext의 부모가 됨
    - 자식 코루틴에서 예외가 발생하면 withContext 코루틴으로 전달이 되고, 잡 취소되고, 자식 코루틴 전부 취소되고, 예외 발생
    - 즉, SupervisorJob이 부모여도 바뀌는 것이 없음

### coroutineScope

- 코루틴 빌더와 달리 부모에 영향을 미치는 대신 try-catch를 이용해 잡을 수 있는 예외를 던짐
- 자세한 내용은 coming soon

## await

- 예외 전파를 멈출 수 있다는 것만으로는 부족할 때가 있다.
- 예외가 발생하면 async 코루틴 빌더도 launch처럼 부모 코루틴을 종료, 관련 다른 코루틴 빌더도 종료시킴
- SupervisorJob/supervisorScope + await를 호출한다면?
    
    ```kotlin
    suspend fun main() = supervisorScope {
        val str1 = async<String> {
            delay(1000)
            throw Exception("")
        }
        
        val str2 = async {
            delay(2000)
            "Text2"
        }
    
        try {
            println(str1.await())
        } catch (e: Exception) {
            println(e)
        }
    
        println(str2.await())
    }
    
    /*
    출력 결과
    -----------
    Exception...
    Text2
    ```
    
    - supervisorScope가 사용되었기 때문에 또 다른 async는 중단되지 않고 끝까지 실행된다!

## CancellationException은 부모까지 전파되지 않는다

- 예외가 CancellationException의 서브클래스라면 부모로 전파되지 않고,
    
    현재 코루틴만 취소시킨다.
    
- Cancellation은 open class → 다른 클래스나 객체로 확장 가능

```kotlin
object MyException : CancellationException()

suspend fun main(): Unit = soroutineScope {
    launch {            // 1
        launch {          // 2
            delay(2000)
            println("Will not be printed")
        }
        throw MyException // 3
    }
    launch {            // 4
        delay(2000)
        println("Will be printed")
    }
}

/*
출력 결과
-----------
Will be printed
```

- 흐름
    - 두 개의 코루틴이 1, 4 빌더로 시작
    - 3에서 CancellationException의 서브 타입인 예외 던짐
    - 이 예외는 1에서 시작된 launch에서 잡힘
    - 1에서 시작된 코루틴은 자기 자신을 취소, 2에서 정의된 자식 코루틴 또한 취소
    - 4에서 시작된 launch는 영향을 받지 않음

## 코루틴 예외 핸들러

- 예외를 처리하는 기본 행동을 정의하고 싶을 때, `CoroutineExceptionHandler` 컨텍스트를 사용하면 편리함
- 예외 전파를 중단시키지는 않지만, 예외가 발생했을 때 해야 할 것들 (기본적으로 예외 스택 트레이스 출력) 을 정의하는 데 사용
    
    ```kotlin
    fun main(): Unit = runBlocking {
        val handler = 
            CoroutineExceptionHandler { ctx, exception ->
                println("Caught $exception")
            }
        val scope = CoroutineScope(SupervisorJob() + handler)
        scope.launch {
            delay(1000)
            throw Error("Some Error")
        }
    
        scope.launch {
            delay(2000)
            println("Will be printed")
        }
    
        delay(3000)
    }
    
    /*
    출력 결과
    -----------
    Caught java.lang.Error: Some error
    Will be printed
    ```
    

- 다양한 플랫폼에서 예외를 처리하는 기본적인 방법으로 `CoroutineExceptionHandler` 컨텍스트를 활용할 수 있음
    - e.g. 안드로이드 - 대화창, 에러 메시지를 보여줌

## 요약

예외 처리 중요하다. *(사실 다 중요하다고 한다)*
