# 10장 예외 처리

Created: March 9, 2024 4:34 PM

코루틴 빌더는 예외 발생 시 부모도 종료시키며, 취소된 부모는 자식들 모두를 취소시킨다.

# 코루틴 종료 멈추기

코루틴 빌더 내부에서 새로운 코루틴 빌더를 try-catch문을 통해 래핑하는 것은 제대로 작동하지않는다.

## SupervisorJob

자식에서 발생한 모든 예외를 무시할 수 있다.

일반적으로 SupervisorJob은 다수의 코루틴을 시작하는 스코프로 사용된다.

```kotlin
fun main(): Unit = runBlocking {
	val scope = CoroutineScope(SupervisorJob())
	scope.launch {
		delay(1000)
		throw Error("Some error")
	}
	
	scope.launch {
		delay(2000)
		println("Will be printed")
	}

	delay(3000)
}
// Exception...
// Will be printed
```

```kotlin
fun main(): Unit = runBlocking {
	// 자식 코루틴 하나가 있고 부모 코루틴이 없는 잡은 일반 잡과 동일하게 작동한다.
	launch(SupervisorJob()) { // 1
	// SupervisorJob이 launch의 자식
		launch {
			delay(1000)
			throw Error("Some error")
		}
		
		launch {
			delay(2000)
			println("Will not be printed")
		}
	}
	
	delay(3000)
}
// Exception...
```

위 코드처럼 SupervisorJob을 부모 코루틴의 인자로 사용하면, SupervisorJob이 자식 단 하나만 가지기 때문에 도움이 되지 않는다. (두 경우 모두 runBlocking의 Job을 사용하지 않아 예외가 runBlocking으로 전파되지 않는다.)

```kotlin
fun main(): Unit = runBlocking {
	val job = SupervisorJob()
	launch(job) {
		delay(1000)
		throw Error("Some error")
	}
	
	launch(job) {
		delay(2000)
		println("Will be printed")
	}
	job.join()
}
// (1초 후)
// Exception...
// (1초 후)
// Will be printed
```

하나의 코루틴이 취소되어도 다른 코루틴이 취소되지 않게, 같은 잡을 다수의 코루틴에서 컨텍스트로 사용하는 것이 좀 더 나은 방법

## supervisorScope

코루틴 빌더를 supervisorScope로 매핑하는 것

다른 코루틴에서 발생한 예외를 무시하고 부모와의 연결을 유지한다.

```kotlin
fun main(): Unit = runBlocking {
	supervisorScope {
		launch {
			delay(1000)
			throw Error("Some error")
		}
		
		launch {
			delay(2000)
			println("Will be printed")
		}
	}
	delay(1000)
	println("Done")
}
// Exception...
// Will be printed
// (1초 후)
// Done
```

일반적으로 서로 무관한 다수의 작업을 스코프 내에서 실행할 때 사용

또 다른 방법으로는 coroutineScope를 사용하는 것이다. 코루틴 빌더와 달리 부모에 영향을 미치는 대신, try-catch를 이용해 잡을 수 있는 예외를 던진다.

supervisorScope ≠ withContext(SupervisorJob())

## await

위까지는 예외 전파를 멈출 수 있는 방법! 이것만으로는 부족할 때는?

```kotlin
class MyException : Throwable()

suspend fun main() = supervisorScope {
	val str1 = async<String> {
		delay(1000)
		throw MyException()
	}
	
	val str2 = async {
		delay(2000)
		"Text2"
	}
	
	try {
		println(str1.await()) // MyException을 던짐, 예외로 종료되어서 반환할 값은 없어도 Exception을 던져서 출력됨
	} catch (e: MyException) {
		println(e) // 받게 되어서 출력
	}
	
	println(str2.await()) // supervisorScope가 사용되었기 때문에 중단되지 않고 출력
}
// MyException
// Text2
```

# CancellationException은 부모까지 전파되지 않는다

예외가 CancellationException의 서브클래스라면 부모로 전파되지 않고 현재 코루틴을 취소시킬 뿐이다.

```kotlin
object MyNonPropagatingException : CancellationException()

suspend fun main(): Unit = coroutineScope {
	launch { // 1
		launch { // 2
			delay(2000)
			println("Will not printed")
		}
		throw MyNonPropagatingException // 3
	}
	launch { // 4
		delay(2000)
		println("Will be printed")
	}
}
// (2초 후)
// Will be printed
```

코루틴 2개 : 1, 4

에서 CancellationException의 서브타입은 MyNonPropagatingException 예외를 던진다. 예외는 1에서 시작된 launch에서 잡히게 되고, 1에서 시작된 코루틴은 자기 자신을 취소하고 2에서 정의된 빌더로 만들어진 자식 코루틴 또한 취소시킨다. 4에서 시작된 두 번째 launch는 영향을 받지 않고 2초 후에 Will be printed를 출력한다.

# 코루틴 예외 핸들러

CoroutineExceptionHandler 컨텍스트를 사용하면 예외를 처리하는 기본 행동을 정의할 수 있다. 예외 전파를 중단시키지는 않지만, 예외 발생 시 해야할 것들을 정의할 수 있다.

```kotlin
fun main(): Unit = runBlocking {
	val handler =
		CoroutineExceptionHandler { ctx, exception ->
			println("Caught $exception")
		}
	
	val scope = CoroutineScope(SupervisorJob() + handler)
	scope.launch {
		delay(1000)
		throw Error("Some error")
	}
	
	scope.launch {
		delay(2000)
		println("Will be printed")
	}

	delay(3000)
}

// Caught java.lang.Error: Some error
// Will be printed
```

안드로이드에서는 사용자에게 대화창이나 에러 메시지를 보여줌으로써 어떤 문제가 발생했는지 알리는 역할을 한다.